Workbook

Sheet C1 Summary
B1: ='C1 System Weights'!E11 -> Subsystem Count | C1: ='C1 System Weights'!E12 -> Deployment Burden | D1: ='C1 System Weights'!E13 -> Operational Flexibility | E1: ='C1 System Weights'!E14 -> Maintenance Demands | F1: ='C1 System Weights'!E15 -> Refuel/Replenish Burden | G1: ='C1 System Weights'!E16 -> Autonomy/Supervision Required
A2: Weights | B2: ='C1 System Weights'!F11 -> 0.16417655 | C2: ='C1 System Weights'!F12 -> 0.18897825 | D2: ='C1 System Weights'!F13 -> 0.21073817 | E2: ='C1 System Weights'!F14 -> 0.12390809 | F2: ='C1 System Weights'!F15 -> 0.051576953 | G2: ='C1 System Weights'!F16 -> 0.26062198 | I2: Ranking
A3: ='DSM Elements'!A1 -> Very Large Air Tankers | B3: 9 | C3: 9 | D3: 5 | E3: 8 | F3: 9 | G3: 6 | I3: =(B3-1)/8*$B$2+(C3-1)/8*$C$2+(D3-1)/8*$D$2+(E3-1)/8*$E$2+(F3-1)/8*$F$2+(G3-1)/8*$G$2 -> 0.78140916 | J3: 0.2
A4: ='DSM Elements'!A2 -> Large Air Tankers | B4: 8 | C4: 8 | D4: 4 | E4: 7 | F4: 8 | G4: 6 | I4: =(B4-1)/8*$B$2+(C4-1)/8*$C$2+(D4-1)/8*$D$2+(E4-1)/8*$E$2+(F4-1)/8*$F$2+(G4-1)/8*$G$2 -> 0.68898691 | J4: 0.2
A5: ='DSM Elements'!A3 -> Single Engine Airtankers | B5: 4 | C5: 4 | D5: 3 | E5: 5 | F5: 6 | G5: 5 | I5: =(B5-1)/8*$B$2+(C5-1)/8*$C$2+(D5-1)/8*$D$2+(E5-1)/8*$E$2+(F5-1)/8*$F$2+(G5-1)/8*$G$2 -> 0.40961823 | J5: 0.2
A6: ='DSM Elements'!A4 -> Water Scoopers | B6: 6 | C6: 5 | D6: 4 | E6: 6 | F6: 5 | G6: 4 | I6: =(B6-1)/8*$B$2+(C6-1)/8*$C$2+(D6-1)/8*$D$2+(E6-1)/8*$E$2+(F6-1)/8*$F$2+(G6-1)/8*$G$2 -> 0.47709056 | J6: 0.2
A7: ='DSM Elements'!A5 -> Military Airborne Firefighting System | B7: 9 | C7: 8 | D7: 3 | E7: 8 | F7: 8 | G7: 7 | I7: =(B7-1)/8*$B$2+(C7-1)/8*$C$2+(D7-1)/8*$D$2+(E7-1)/8*$E$2+(F7-1)/8*$F$2+(G7-1)/8*$G$2 -> 0.73123296 | J7: 0.2
A8: ='DSM Elements'!A6 -> Helicopters Type I | B8: 8 | C8: 6 | D8: 2 | E8: 7 | F8: 7 | G8: 6 | I8: =(B8-1)/8*$B$2+(C8-1)/8*$C$2+(D8-1)/8*$D$2+(E8-1)/8*$E$2+(F8-1)/8*$F$2+(G8-1)/8*$G$2 -> 0.58261068 | J8: 0.2
A9: ='DSM Elements'!A7 -> Helicopters Type II | B9: 6 | C9: 5 | D9: 3 | E9: 6 | F9: 6 | G9: 5 | I9: =(B9-1)/8*$B$2+(C9-1)/8*$C$2+(D9-1)/8*$D$2+(E9-1)/8*$E$2+(F9-1)/8*$F$2+(G9-1)/8*$G$2 -> 0.48977315 | J9: 0.2
A10: ='DSM Elements'!A8 -> Helicopters Type III | B10: 5 | C10: 4 | D10: 4 | E10: 5 | F10: 5 | G10: 4 | I10: =(B10-1)/8*$B$2+(C10-1)/8*$C$2+(D10-1)/8*$D$2+(E10-1)/8*$E$2+(F10-1)/8*$F$2+(G10-1)/8*$G$2 -> 0.4174577 | J10: 0.2
A11: ='DSM Elements'!A9 -> Tactical Lead Planes | B11: 6 | C11: 5 | D11: 2 | E11: 6 | F11: 7 | G11: 5 | I11: =(B11-1)/8*$B$2+(C11-1)/8*$C$2+(D11-1)/8*$D$2+(E11-1)/8*$E$2+(F11-1)/8*$F$2+(G11-1)/8*$G$2 -> 0.469878 | J11: 0.2
A12: ='DSM Elements'!A10 -> Air Attack Group Supervisor (AAGS) | B12: 5 | C12: 4 | D12: 1 | E12: 5 | F12: 6 | G12: 5 | I12: =(B12-1)/8*$B$2+(C12-1)/8*$C$2+(D12-1)/8*$D$2+(E12-1)/8*$E$2+(F12-1)/8*$F$2+(G12-1)/8*$G$2 -> 0.37745575 | J12: 0.2
A13: ='DSM Elements'!A11 -> Smokejumper Aircraft | B13: 5 | C13: 5 | D13: 4 | E13: 6 | F13: 7 | G13: 4 | I13: =(B13-1)/8*$B$2+(C13-1)/8*$C$2+(D13-1)/8*$D$2+(E13-1)/8*$E$2+(F13-1)/8*$F$2+(G13-1)/8*$G$2 -> 0.46946273 | J13: 0.2
A14: ='DSM Elements'!A12 -> Tactical UAS | B14: 6 | C14: 3 | D14: 3 | E14: 4 | F14: 4 | G14: 3 | I14: =(B14-1)/8*$B$2+(C14-1)/8*$C$2+(D14-1)/8*$D$2+(E14-1)/8*$E$2+(F14-1)/8*$F$2+(G14-1)/8*$G$2 -> 0.33350184 | J14: 0.2
... A22: ='DSM Elements'!A20 -> C3 Systems | B22: 9 | C22: 2 | D22: 2 | E22: 6 | F22: 5 | G22: 5 | I22: =(B22-1)/8*$B$2+(C22-1)/8*$C$2+(D22-1)/8*$D$2+(E22-1)/8*$E$2+(F22-1)/8*$F$2+(G22-1)/8*$G$2 -> 0.44768312 | J22: 0.2
B25: ='C1 System Weights'!E22 -> Cognitive Load | C25: ='C1 System Weights'!E23 -> Temporal Criticality | D25: ='C1 System Weights'!E24 -> Interdependency/Process Coupling | E25: ='C1 System Weights'!E25 -> Execution Steps | F25: ='C1 System Weights'!E26 -> Resource Footprint | G25: ='C1 System Weights'!E27 -> Operational Risk
A26: Weights | B26: ='C1 System Weights'!F22 -> 0.20182026 | C26: ='C1 System Weights'!F23 -> 0.24094347 | D26: ='C1 System Weights'!F24 -> 0.066358507 | E26: ='C1 System Weights'!F25 -> 0.033021901 | F26: ='C1 System Weights'!F26 -> 0.096869567 | G26: ='C1 System Weights'!F27 -> 0.36098629 | I26: Ranking
A27: ='DSM Elements'!A21 -> Deploy Air Assets | B27: 5 | C27: 8 | D27: 7 | E27: 6 | F27: 7 | G27: 8 | I27: =(B27-1)/8*$B$26+(C27-1)/8*$C$26+(D27-1)/8*$D$26+(E27-1)/8*$E$26+(F27-1)/8*$F$26+(G27-1)/8*$G$26 -> 0.77065842 | J27: 1
A28: ='DSM Elements'!A22 -> Lead Tankers | B28: 7 | C28: 9 | D28: 8 | E28: 7 | F28: 8 | G28: 9 | I28: =(B28-1)/8*$B$26+(C28-1)/8*$C$26+(D28-1)/8*$D$26+(E28-1)/8*$E$26+(F28-1)/8*$F$26+(G28-1)/8*$G$26 -> 0.92088595 | J28: 1
A29: ='DSM Elements'!A23 -> Supervise Air Attacks (AAGs) | B29: 8 | C29: 9 | D29: 9 | E29: 8 | F29: 8 | G29: 9 | I29: =(B29-1)/8*$B$26+(C29-1)/8*$C$26+(D29-1)/8*$D$26+(E29-1)/8*$E$26+(F29-1)/8*$F$26+(G29-1)/8*$G$26 -> 0.95853603 | J29: 1
A30: ='DSM Elements'!A24 -> Drop Water | B30: 3 | C30: 9 | D30: 6 | E30: 3 | F30: 6 | G30: 7 | I30: =(B30-1)/8*$B$26+(C30-1)/8*$C$26+(D30-1)/8*$D$26+(E30-1)/8*$E$26+(F30-1)/8*$F$26+(G30-1)/8*$G$26 -> 0.67241128 | J30: 1
A31: ='DSM Elements'!A25 -> Drop Fire Retardant | B31: 3 | C31: 9 | D31: 6 | E31: 3 | F31: 6 | G31: 7 | I31: =(B31-1)/8*$B$26+(C31-1)/8*$C$26+(D31-1)/8*$D$26+(E31-1)/8*$E$26+(F31-1)/8*$F$26+(G31-1)/8*$G$26 -> 0.67241128 | J31: 1
A32: ='DSM Elements'!A26 -> Perform Post-Drop Assessment | B32: 5 | C32: 6 | D32: 7 | E32: 5 | F32: 5 | G32: 5 | I32: =(B32-1)/8*$B$26+(C32-1)/8*$C$26+(D32-1)/8*$D$26+(E32-1)/8*$E$26+(F32-1)/8*$F$26+(G32-1)/8*$G$26 -> 0.54670756 | J32: 1
A33: ='DSM Elements'!A27 -> Dispatch To Reloading Base | B33: 2 | C33: 5 | D33: 5 | E33: 3 | F33: 4 | G33: 4 | I33: =(B33-1)/8*$B$26+(C33-1)/8*$C$26+(D33-1)/8*$D$26+(E33-1)/8*$E$26+(F33-1)/8*$F$26+(G33-1)/8*$G$26 -> 0.35882994 | J33: 1
A34: ='DSM Elements'!A28 -> Deploy Ground Assets | B34: 4 | C34: 7 | D34: 7 | E34: 6 | F34: 7 | G34: 7 | I34: =(B34-1)/8*$B$26+(C34-1)/8*$C$26+(D34-1)/8*$D$26+(E34-1)/8*$E$26+(F34-1)/8*$F$26+(G34-1)/8*$G$26 -> 0.67018966 | J34: 1
A35: ='DSM Elements'!A29 -> Establish Containment Lines | B35: 6 | C35: 8 | D35: 8 | E35: 7 | F35: 8 | G35: 8 | I35: =(B35-1)/8*$B$26+(C35-1)/8*$C$26+(D35-1)/8*$D$26+(E35-1)/8*$E$26+(F35-1)/8*$F$26+(G35-1)/8*$G$26 -> 0.8204172 | J35: 1
A36: ='DSM Elements'!A30 -> Spill Water from Ground Assets | B36: 2 | C36: 7 | D36: 5 | E36: 3 | F36: 4 | G36: 5 | I36: =(B36-1)/8*$B$26+(C36-1)/8*$C$26+(D36-1)/8*$D$26+(E36-1)/8*$E$26+(F36-1)/8*$F$26+(G36-1)/8*$G$26 -> 0.4641891 | J36: 1
A37: ='DSM Elements'!A31 -> Tactically Monitor Fires | B37: 6 | C37: 7 | D37: 6 | E37: 6 | F37: 6 | G37: 6 | I37: =(B37-1)/8*$B$26+(C37-1)/8*$C$26+(D37-1)/8*$D$26+(E37-1)/8*$E$26+(F37-1)/8*$F$26+(G37-1)/8*$G$26 -> 0.65511793 | J37: 1
A38: ='DSM Elements'!A32 -> Predict New Fires | B38: 7 | C38: 5 | D38: 6 | E38: 5 | F38: 5 | G38: 6 | I38: =(B38-1)/8*$B$26+(C38-1)/8*$C$26+(D38-1)/8*$D$26+(E38-1)/8*$E$26+(F38-1)/8*$F$26+(G38-1)/8*$G$26 -> 0.60387317 | J38: 1
... A57: ='DSM Elements'!A51 -> Provide Logistic Support to Crews | B57: 4 | C57: 6 | D57: 6 | E57: 6 | F57: 6 | G57: 6 | I57: =(B57-1)/8*$B$26+(C57-1)/8*$C$26+(D57-1)/8*$D$26+(E57-1)/8*$E$26+(F57-1)/8*$F$26+(G57-1)/8*$G$26 -> 0.57454493 | J57: 1
B60: ='C1 System Weights'!E32 -> Jurisdictional Breadth | C60: ='C1 System Weights'!E33 -> Coordination Span | D60: ='C1 System Weights'!E34 -> Legal/Bureaucratic Constraints | E60: ='C1 System Weights'!E35 -> Mandate Breadth | F60: ='C1 System Weights'!E36 -> Resource Management Burden | G60: ='C1 System Weights'!E37 -> Policy/Political Sensitivity | H60: ='C1 System Weights'!E38 -> Activation/Response Latency
A61: Weights | B61: ='C1 System Weights'!F32 -> 0.171078 | C61: ='C1 System Weights'!F33 -> 0.1551578 | D61: ='C1 System Weights'!F34 -> 0.056705039 | E61: ='C1 System Weights'!F35 -> 0.19479604 | F61: ='C1 System Weights'!F36 -> 0.22053918 | G61: ='C1 System Weights'!F37 -> 0.15599746 | H61: ='C1 System Weights'!F38 -> 0.045726469 | I61: Ranking
A62: ='DSM Elements'!A52 -> Federal Emergency Management Agency | B62: 8 | C62: 9 | D62: 7 | E62: 8 | F62: 8 | G62: 8 | H62: 6 | I62: =(B62-1)/8*$B$61+(C62-1)/8*$C$61+(D62-1)/8*$D$61+(E62-1)/8*$E$61+(F62-1)/8*$F$61+(G62-1)/8*$G$61+(H62-1)/8*$H$61 -> 0.87587498 | J62: 0.4
A63: ='DSM Elements'!A53 -> National Interagency Fire Center | B63: 7 | C63: 8 | D63: 6 | E63: 7 | F63: 7 | G63: 6 | H63: 5 | I63: =(B63-1)/8*$B$61+(C63-1)/8*$C$61+(D63-1)/8*$D$61+(E63-1)/8*$E$61+(F63-1)/8*$F$61+(G63-1)/8*$G$61+(H63-1)/8*$H$61 -> 0.73137529 | J63: 0.4
A64: ='DSM Elements'!A54 -> Environmental Protection Agency | B64: 6 | C64: 7 | D64: 8 | E64: 5 | F64: 5 | G64: 9 | H64: 7 | I64: =(B64-1)/8*$B$61+(C64-1)/8*$C$61+(D64-1)/8*$D$61+(E64-1)/8*$E$61+(F64-1)/8*$F$61+(G64-1)/8*$G$61+(H64-1)/8*$H$61 -> 0.67086894 | J64: 0.4
A65: ='DSM Elements'!A55 -> Military Organizations (US National Guard/DOD) | B65: 9 | C65: 9 | D65: 9 | E65: 9 | F65: 9 | G65: 9 | H65: 8 | I65: =(B65-1)/8*$B$61+(C65-1)/8*$C$61+(D65-1)/8*$D$61+(E65-1)/8*$E$61+(F65-1)/8*$F$61+(G65-1)/8*$G$61+(H65-1)/8*$H$61 -> 0.99428419 | J65: 0.4
A66: ='DSM Elements'!A56 -> Manufacturers Of VLAT/LAT | B66: 3 | C66: 3 | D66: 2 | E66: 3 | F66: 4 | G66: 2 | H66: 2 | I66: =(B66-1)/8*$B$61+(C66-1)/8*$C$61+(D66-1)/8*$D$61+(E66-1)/8*$E$61+(F66-1)/8*$F$61+(G66-1)/8*$G$61+(H66-1)/8*$H$61 -> 0.24526378 | J66: 0.4
A67: ='DSM Elements'!A57 -> Manufacturers Of Lead Plane & AAGS | B67: 3 | C67: 3 | D67: 2 | E67: 3 | F67: 3 | G67: 2 | H67: 2 | I67: =(B67-1)/8*$B$61+(C67-1)/8*$C$61+(D67-1)/8*$D$61+(E67-1)/8*$E$61+(F67-1)/8*$F$61+(G67-1)/8*$G$61+(H67-1)/8*$H$61 -> 0.21769638 | J67: 0.4
A68: ='DSM Elements'!A58 -> Satellite Manufacturers | B68: 6 | C68: 5 | D68: 3 | E68: 4 | F68: 6 | G68: 3 | H68: 3 | I68: =(B68-1)/8*$B$61+(C68-1)/8*$C$61+(D68-1)/8*$D$61+(E68-1)/8*$E$61+(F68-1)/8*$F$61+(G68-1)/8*$G$61+(H68-1)/8*$H$61 -> 0.4599954 | J68: 0.4
A69: ='DSM Elements'!A59 -> UAS Manufacturers | B69: 4 | C69: 5 | D69: 3 | E69: 3 | F69: 5 | G69: 3 | H69: 3 | I69: =(B69-1)/8*$B$61+(C69-1)/8*$C$61+(D69-1)/8*$D$61+(E69-1)/8*$E$61+(F69-1)/8*$F$61+(G69-1)/8*$G$61+(H69-1)/8*$H$61 -> 0.365309 | J69: 0.4
...

Sheet C1 System Weights
B2: Rankings | E2: Key Note:
B3: Importance | C3: Definition | E3: Type metric name in gray
B4: 1 | C4: Equal Complexity | E4: Only type comparison values in white areas
B5: 3 | C5: Moderate Complexity
B6: 5 | C6: Strong Complexity | E6: You have to open in the desktop app to copy and paste with the formulas
B7: 7 | C7: Very Strong Complexity
B8: 9 | C8: Extreme Complexity
E10: Metric | F10: Criticality Weights | G10: =E11 -> Subsystem Count | H10: =E12 -> Deployment Burden | I10: =E13 -> Operational Flexibility | J10: =E14 -> Maintenance Demands | K10: =E15 -> Refuel/Replenish Burden | L10: =E16 -> Autonomy/Supervision Required | O10: Metric | P10: Relative Importance
E11: Subsystem Count | F11: =AVERAGE(R11:W11) -> 0.16417655 | G11: 1 | H11: 2 | I11: 0.33333333 | J11: 1 | K11: 3 | L11: 1 | O11: =E11 -> Subsystem Count | P11: =F11 -> 0.16417655 | R11: =G11/SUM(G$11:G$16) -> 0.14634146 | S11: =H11/SUM(H$11:H$16) -> 0.26845638 | T11: =I11/SUM(I$11:I$16) -> 0.055555556 | U11: =J11/SUM(J$11:J$16) -> 0.088235294 | V11: =K11/SUM(K$11:K$16) -> 0.17647059 | W11: =L11/SUM(L$11:L$16) -> 0.25
E12: Deployment Burden | F12: =AVERAGE(R12:W12) -> 0.18897825 | G12: {=1/INDEX($H$11:$M$11, 1, ROW(A1))} -> 0.5 | H12: 1 | I12: 1 | J12: 5 | K12: 4 | L12: 0.33333333 | O12: =E12 -> Deployment Burden | P12: =F12 -> 0.18897825 | R12: =G12/SUM(G$11:G$16) -> 0.073170732 | S12: =H12/SUM(H$11:H$16) -> 0.13422819 | T12: =I12/SUM(I$11:I$16) -> 0.16666667 | U12: =J12/SUM(J$11:J$16) -> 0.44117647 | V12: =K12/SUM(K$11:K$16) -> 0.23529412 | W12: =L12/SUM(L$11:L$16) -> 0.083333333
E13: Operational Flexibility | F13: =AVERAGE(R13:W13) -> 0.21073817 | G13: {=1/INDEX($H$11:$M$11, 1, ROW(A2))} -> 3 | H13: {=1/INDEX($I$12:$M$12, 1, ROW(A1))} -> 1 | I13: 1 | J13: 3 | K13: 3 | L13: 0.33333333 | O13: =E13 -> Operational Flexibility | P13: =F13 -> 0.21073817 | R13: =G13/SUM(G$11:G$16) -> 0.43902439 | S13: =H13/SUM(H$11:H$16) -> 0.13422819 | T13: =I13/SUM(I$11:I$16) -> 0.16666667 | U13: =J13/SUM(J$11:J$16) -> 0.26470588 | V13: =K13/SUM(K$11:K$16) -> 0.17647059 | W13: =L13/SUM(L$11:L$16) -> 0.083333333
E14: Maintenance Demands | F14: =AVERAGE(R14:W14) -> 0.12390809 | G14: {=1/INDEX($H$11:$M$11, 1, ROW(A3))} -> 1 | H14: {=1/INDEX($I$12:$M$12, 1, ROW(A2))} -> 0.2 | I14: {=1/INDEX($J$13:$M$13, 1, ROW(A1))} -> 0.33333333 | J14: 1 | K14: 3 | L14: 1 | O14: =E14 -> Maintenance Demands | P14: =F14 -> 0.12390809 | R14: =G14/SUM(G$11:G$16) -> 0.14634146 | S14: =H14/SUM(H$11:H$16) -> 0.026845638 | T14: =I14/SUM(I$11:I$16) -> 0.055555556 | U14: =J14/SUM(J$11:J$16) -> 0.088235294 | V14: =K14/SUM(K$11:K$16) -> 0.17647059 | W14: =L14/SUM(L$11:L$16) -> 0.25
E15: Refuel/Replenish Burden | F15: =AVERAGE(R15:W15) -> 0.051576953 | G15: {=1/INDEX($H$11:$M$11, 1, ROW(A4))} -> 0.33333333 | H15: {=1/INDEX($I$12:$M$12, 1, ROW(A3))} -> 0.25 | I15: {=1/INDEX($J$13:$M$13, 1, ROW(A2))} -> 0.33333333 | J15: {=1/INDEX($K$14:$M$14, 1, ROW(A1))} -> 0.33333333 | K15: 1 | L15: 0.33333333 | O15: =E15 -> Refuel/Replenish Burden | P15: =F15 -> 0.051576953 | R15: =G15/SUM(G$11:G$16) -> 0.048780488 | S15: =H15/SUM(H$11:H$16) -> 0.033557047 | T15: =I15/SUM(I$11:I$16) -> 0.055555556 | U15: =J15/SUM(J$11:J$16) -> 0.029411765 | V15: =K15/SUM(K$11:K$16) -> 0.058823529 | W15: =L15/SUM(L$11:L$16) -> 0.083333333
E16: Autonomy/Supervision Required | F16: =AVERAGE(R16:W16) -> 0.26062198 | G16: {=1/INDEX($H$11:$M$11, 1, ROW(A5))} -> 1 | H16: {=1/INDEX($I$12:$M$12, 1, ROW(A4))} -> 3 | I16: {=1/INDEX($J$13:$M$13, 1, ROW(A3))} -> 3 | J16: {=1/INDEX($K$14:$M$14, 1, ROW(A2))} -> 1 | K16: {=1/INDEX($L$15:$M$15, 1, ROW(A1))} -> 3 | L16: 1 | O16: =E16 -> Autonomy/Supervision Required | P16: =F16 -> 0.26062198 | R16: =G16/SUM(G$11:G$16) -> 0.14634146 | S16: =H16/SUM(H$11:H$16) -> 0.40268456 | T16: =I16/SUM(I$11:I$16) -> 0.5 | U16: =J16/SUM(J$11:J$16) -> 0.088235294 | V16: =K16/SUM(K$11:K$16) -> 0.17647059 | W16: =L16/SUM(L$11:L$16) -> 0.25
F17: =SUM(F11:F16) -> 1
E21: Metric | F21: Criticality Weights | G21: =E22 -> Cognitive Load | H21: =E23 -> Temporal Criticality | I21: =E24 -> Interdependency/Process Coupling | J21: =E25 -> Execution Steps | K21: =E26 -> Resource Footprint | L21: =E27 -> Operational Risk | O21: Metric | P21: Relative Importance
E22: Cognitive Load | F22: =AVERAGE(R22:W22) -> 0.20182026 | G22: 1 | H22: 0.33333333 | I22: 3 | J22: 5 | K22: 3 | L22: 1 | O22: =E22 -> Cognitive Load | P22: =F22 -> 0.20182026 | R22: =G22/SUM(G$22:G$27) -> 0.17045455 | S22: =H22/SUM(H$22:H$27) -> 0.064102564 | T22: =I22/SUM(I$22:I$27) -> 0.19565217 | U22: =J22/SUM(J$22:J$27) -> 0.19230769 | V22: =K22/SUM(K$22:K$27) -> 0.23684211 | W22: =L22/SUM(L$22:L$27) -> 0.3515625
E23: Temporal Criticality | F23: =AVERAGE(R23:W23) -> 0.24094347 | G23: {=1/INDEX($H$22:$M$22, 1, ROW($A1))} -> 3 | H23: 1 | I23: 3 | J23: 5 | K23: 3 | L23: 0.33333333 | O23: =E23 -> Temporal Criticality | P23: =F23 -> 0.24094347 | R23: =G23/SUM(G$22:G$27) -> 0.51136364 | S23: =H23/SUM(H$22:H$27) -> 0.19230769 | T23: =I23/SUM(I$22:I$27) -> 0.19565217 | U23: =J23/SUM(J$22:J$27) -> 0.19230769 | V23: =K23/SUM(K$22:K$27) -> 0.23684211 | W23: =L23/SUM(L$22:L$27) -> 0.1171875
E24: Interdependency/Process Coupling | F24: =AVERAGE(R24:W24) -> 0.066358507 | G24: {=1/INDEX($H$22:$M$22, 1, ROW($A2))} -> 0.33333333 | H24: {=1/INDEX($I$23:$M$23, 1, ROW($A1))} -> 0.33333333 | I24: 1 | J24: 3 | K24: 0.33333333 | L24: 0.2 | O24: =E24 -> Interdependency/Process Coupling | P24: =F24 -> 0.066358507 | R24: =G24/SUM(G$22:G$27) -> 0.056818182 | S24: =H24/SUM(H$22:H$27) -> 0.064102564 | T24: =I24/SUM(I$22:I$27) -> 0.065217391 | U24: =J24/SUM(J$22:J$27) -> 0.11538462 | V24: =K24/SUM(K$22:K$27) -> 0.026315789 | W24: =L24/SUM(L$22:L$27) -> 0.0703125
E25: Execution Steps | F25: =AVERAGE(R25:W25) -> 0.033021901 | G25: {=1/INDEX($H$22:$M$22, 1, ROW($A3))} -> 0.2 | H25: {=1/INDEX($I$23:$M$23, 1, ROW($A2))} -> 0.2 | I25: {=1/INDEX($J$24:$M$24, 1, ROW($A1))} -> 0.33333333 | J25: 1 | K25: 0.33333333 | L25: =1/9 -> 0.11111111 | O25: =E25 -> Execution Steps | P25: =F25 -> 0.033021901 | R25: =G25/SUM(G$22:G$27) -> 0.034090909 | S25: =H25/SUM(H$22:H$27) -> 0.038461538 | T25: =I25/SUM(I$22:I$27) -> 0.02173913 | U25: =J25/SUM(J$22:J$27) -> 0.038461538 | V25: =K25/SUM(K$22:K$27) -> 0.026315789 | W25: =L25/SUM(L$22:L$27) -> 0.0390625
E26: Resource Footprint | F26: =AVERAGE(R26:W26) -> 0.096869567 | G26: {=1/INDEX($H$22:$M$22, 1, ROW($A4))} -> 0.33333333 | H26: {=1/INDEX($I$23:$M$23, 1, ROW($A3))} -> 0.33333333 | I26: {=1/INDEX($J$24:$M$24, 1, ROW($A2))} -> 3 | J26: {=1/INDEX($K$25:$M$25, 1, ROW($A1))} -> 3 | K26: 1 | L26: 0.2 | O26: =E26 -> Resource Footprint | P26: =F26 -> 0.096869567 | R26: =G26/SUM(G$22:G$27) -> 0.056818182 | S26: =H26/SUM(H$22:H$27) -> 0.064102564 | T26: =I26/SUM(I$22:I$27) -> 0.19565217 | U26: =J26/SUM(J$22:J$27) -> 0.11538462 | V26: =K26/SUM(K$22:K$27) -> 0.078947368 | W26: =L26/SUM(L$22:L$27) -> 0.0703125
E27: Operational Risk | F27: =AVERAGE(R27:W27) -> 0.36098629 | G27: {=1/INDEX($H$22:$M$22, 1, ROW($A5))} -> 1 | H27: {=1/INDEX($I$23:$M$23, 1, ROW($A4))} -> 3 | I27: {=1/INDEX($J$24:$M$24, 1, ROW($A3))} -> 5 | J27: {=1/INDEX($K$25:$M$25, 1, ROW($A2))} -> 9 | K27: {=1/INDEX($L$26:$M$26, 1, ROW($A1))} -> 5 | L27: 1 | O27: =E27 -> Operational Risk | P27: =F27 -> 0.36098629 | R27: =G27/SUM(G$22:G$27) -> 0.17045455 | S27: =H27/SUM(H$22:H$27) -> 0.57692308 | T27: =I27/SUM(I$22:I$27) -> 0.32608696 | U27: =J27/SUM(J$22:J$27) -> 0.34615385 | V27: =K27/SUM(K$22:K$27) -> 0.39473684 | W27: =L27/SUM(L$22:L$27) -> 0.3515625
F28: =SUM(F22:F27) -> 1
E31: Metric | F31: Criticality Weights | G31: =E32 -> Jurisdictional Breadth | H31: =E33 -> Coordination Span | I31: =E34 -> Legal/Bureaucratic Constraints | J31: =E35 -> Mandate Breadth | K31: =E36 -> Resource Management Burden | L31: =E37 -> Policy/Political Sensitivity | M31: =E38 -> Activation/Response Latency | O31: Metric | P31: Relative Importance
E32: Jurisdictional Breadth | F32: =AVERAGE(R32:X32) -> 0.171078 | G32: 1 | H32: 1 | I32: 5 | J32: 1 | K32: 1 | L32: 1 | M32: 3 | O32: =E32 -> Jurisdictional Breadth | P32: =F32 -> 0.171078 | R32: =G32/SUM(G$32:G$38) -> 0.18072289 | S32: =H32/SUM(H$32:H$38) -> 0.13274336 | T32: =I32/SUM(I$32:I$38) -> 0.26315789 | U32: =J32/SUM(J$32:J$38) -> 0.14563107 | V32: =K32/SUM(K$32:K$38) -> 0.21126761 | W32: =L32/SUM(L$32:L$38) -> 0.12765957 | X32: =M32/SUM(M$32:M$38) -> 0.13636364
E33: Coordination Span | F33: =AVERAGE(R33:X33) -> 0.1551578 | G33: {=1/INDEX($H$32:$M$32, 1, ROW($A1))} -> 1 | H33: 1 | I33: 3 | J33: 0.33333333 | K33: 1 | L33: 1 | M33: 5 | O33: =E33 -> Coordination Span | P33: =F33 -> 0.1551578 | R33: =G33/SUM(G$32:G$38) -> 0.18072289 | S33: =H33/SUM(H$32:H$38) -> 0.13274336 | T33: =I33/SUM(I$32:I$38) -> 0.15789474 | U33: =J33/SUM(J$32:J$38) -> 0.048543689 | V33: =K33/SUM(K$32:K$38) -> 0.21126761 | W33: =L33/SUM(L$32:L$38) -> 0.12765957 | X33: =M33/SUM(M$32:M$38) -> 0.22727273
E34: Legal/Bureaucratic Constraints | F34: =AVERAGE(R34:X34) -> 0.056705039 | G34: {=1/INDEX($H$32:$M$32, 1, ROW($A2))} -> 0.2 | H34: {=1/INDEX($I$33:$M$33, 1, ROW($A1))} -> 0.33333333 | I34: 1 | J34: 0.33333333 | K34: 0.2 | L34: 1 | M34: 1 | O34: =E34 -> Legal/Bureaucratic Constraints | P34: =F34 -> 0.056705039 | R34: =G34/SUM(G$32:G$38) -> 0.036144578 | S34: =H34/SUM(H$32:H$38) -> 0.044247788 | T34: =I34/SUM(I$32:I$38) -> 0.052631579 | U34: =J34/SUM(J$32:J$38) -> 0.048543689 | V34: =K34/SUM(K$32:K$38) -> 0.042253521 | W34: =L34/SUM(L$32:L$38) -> 0.12765957 | X34: =M34/SUM(M$32:M$38) -> 0.045454545
E35: Mandate Breadth | F35: =AVERAGE(R35:X35) -> 0.19479604 | G35: {=1/INDEX($H$32:$M$32, 1, ROW($A3))} -> 1 | H35: {=1/INDEX($I$33:$M$33, 1, ROW($A2))} -> 3 | I35: {=1/INDEX($J$34:$M$34, 1, ROW($A1))} -> 3 | J35: 1 | K35: 1 | L35: 0.33333333 | M35: 5 | O35: =E35 -> Mandate Breadth | P35: =F35 -> 0.19479604 | R35: =G35/SUM(G$32:G$38) -> 0.18072289 | S35: =H35/SUM(H$32:H$38) -> 0.39823009 | T35: =I35/SUM(I$32:I$38) -> 0.15789474 | U35: =J35/SUM(J$32:J$38) -> 0.14563107 | V35: =K35/SUM(K$32:K$38) -> 0.21126761 | W35: =L35/SUM(L$32:L$38) -> 0.042553191 | X35: =M35/SUM(M$32:M$38) -> 0.22727273
E36: Resource Management Burden | F36: =AVERAGE(R36:X36) -> 0.22053918 | G36: {=1/INDEX($H$32:$M$32, 1, ROW($A4))} -> 1 | H36: {=1/INDEX($I$33:$M$33, 1, ROW($A3))} -> 1 | I36: {=1/INDEX($J$34:$M$34, 1, ROW($A2))} -> 5 | J36: {=1/INDEX($K$35:$M$35, 1, ROW($A1))} -> 1 | K36: 1 | L36: 3 | M36: 5 | O36: =E36 -> Resource Management Burden | P36: =F36 -> 0.22053918 | R36: =G36/SUM(G$32:G$38) -> 0.18072289 | S36: =H36/SUM(H$32:H$38) -> 0.13274336 | T36: =I36/SUM(I$32:I$38) -> 0.26315789 | U36: =J36/SUM(J$32:J$38) -> 0.14563107 | V36: =K36/SUM(K$32:K$38) -> 0.21126761 | W36: =L36/SUM(L$32:L$38) -> 0.38297872 | X36: =M36/SUM(M$32:M$38) -> 0.22727273
E37: Policy/Political Sensitivity | F37: =AVERAGE(R37:X37) -> 0.15599746 | G37: {=1/INDEX($H$32:$M$32, 1, ROW($A5))} -> 1 | H37: {=1/INDEX($I$33:$M$33, 1, ROW($A4))} -> 1 | I37: {=1/INDEX($J$34:$M$34, 1, ROW($A3))} -> 1 | J37: {=1/INDEX($K$35:$M$35, 1, ROW($A2))} -> 3 | K37: {=1/INDEX($L$36:$M$36, 1, ROW($A1))} -> 0.33333333 | L37: 1 | M37: 2 | O37: =E37 -> Policy/Political Sensitivity | P37: =F37 -> 0.15599746 | R37: =G37/SUM(G$32:G$38) -> 0.18072289 | S37: =H37/SUM(H$32:H$38) -> 0.13274336 | T37: =I37/SUM(I$32:I$38) -> 0.052631579 | U37: =J37/SUM(J$32:J$38) -> 0.4368932 | V37: =K37/SUM(K$32:K$38) -> 0.070422535 | W37: =L37/SUM(L$32:L$38) -> 0.12765957 | X37: =M37/SUM(M$32:M$38) -> 0.090909091
E38: Activation/Response Latency | F38: =AVERAGE(R38:X38) -> 0.045726469 | G38: {=1/INDEX($H$32:$M$32, 1, ROW($A6))} -> 0.33333333 | H38: {=1/INDEX($I$33:$M$33, 1, ROW($A5))} -> 0.2 | I38: {=1/INDEX($J$34:$M$34, 1, ROW($A4))} -> 1 | J38: {=1/INDEX($K$35:$M$35, 1, ROW($A3))} -> 0.2 | K38: {=1/INDEX($L$36:$M$36, 1, ROW($A2))} -> 0.2 | L38: {=1/INDEX($M$37:$M$37, 1, ROW($A1))} -> 0.5 | M38: 1 | O38: =E38 -> Activation/Response Latency | P38: =F38 -> 0.045726469 | R38: =G38/SUM(G$32:G$38) -> 0.060240964 | S38: =H38/SUM(H$32:H$38) -> 0.026548673 | T38: =I38/SUM(I$32:I$38) -> 0.052631579 | U38: =J38/SUM(J$32:J$38) -> 0.029126214 | V38: =K38/SUM(K$32:K$38) -> 0.042253521 | W38: =L38/SUM(L$32:L$38) -> 0.063829787 | X38: =M38/SUM(M$32:M$38) -> 0.045454545
F39: =SUM(F32:F38) -> 1

Sheet C1 Metric Descriptions
A1: Element Type | B1: Metric | C1: Description
A2: Structural | B2: Subsystem Count | C2: Number and diversity of onboard subsystems (avionics, propulsion, sensors, etc.). More = higher complexity.
A3: Structural | B3: Deployment Burden | C3: Difficulty in deploying or positioning the asset (e.g., launch, airlift, driving terrain).
A4: Structural | B4: Operational Flexibility | C4: Number of distinct roles it can fulfill (e.g., surveillance, suppression, transport).
A5: Structural | B5: Maintenance Demands | C5: Frequency, difficulty, and time required for upkeep or repair.
A6: Structural | B6: Refueling / Replenishment Burden | C6: Logistics of keeping the asset mission-ready (e.g., fueling, retardant loading).
A7: Structural | B7: Autonomy / Supervision Requirement | C7: Level of human supervision or remote control required (e.g., satellite = low, drone = high).
A8: Functional | B8: Cognitive Load | C8: Complexity of human decision-making or judgment needed to perform the task.
A9: Functional | B9: Temporal Criticality | C9: How time-sensitive the function is for mission success (e.g., suppression vs. comms).
A10: Functional | B10: Interdependency / Process Coupling | C10: Degree of dependency on other functions to execute effectively.
A11: Functional | B11: Execution Steps | C11: Number of steps, phases, or sub-functions involved.
A12: Functional | B12: Resource Footprint | C12: Quantity and diversity of assets required (e.g., aircraft, personnel, data links).
... A20: Organizational | B20: Activation / Response Latency | C20: Time and effort required to mobilize the organization into active operations.

Sheet DSM Elements
A1: Very Large Air Tankers
A2: Large Air Tankers
A3: Single Engine Airtankers
A4: Water Scoopers
A5: Military Airborne Firefighting System
A6: Helicopters Type I
A7: Helicopters Type II
A8: Helicopters Type III
A9: Tactical Lead Planes
A10: Air Attack Group Supervisor (AAGS)
A11: Smokejumper Aircraft
A12: Tactical UAS
... A84: Government of Canada

Sheet C2 Interface Weights
B2: Rankings | E2: Key Note:
B3: Importance | C3: Definition | E3: Type metric name in gray
B4: 1 | C4: Equal Complexity | E4: Only type comparison values in white areas
B5: 3 | C5: Moderate Complexity
B6: 5 | C6: Strong Complexity | E6: You have to open in the desktop app to copy and paste with the formulas
B7: 7 | C7: Very Strong Complexity
B8: 9 | C8: Extreme Complexity
E10: Functions | F10: Criticality Weights | G10: =E11 -> Mass | H10: =E12 -> Information | I10: =E13 -> Physical | J10: =E14 -> Energy | K10: =E15 -> Contribution | L10: =E16 -> Development | M10: =E17 -> Operation | N10: =E18 -> Service | O10: =E19 -> Prerequisite | P10: =E20 -> Coordination | Q10: =E21 -> Definition | R10: =E22 -> Contractual | S10: =E23 -> Deliverable | T10: =E24 -> Financial | U10: =E25 -> Legal | V10: =E26 -> Political | X10: Interface | Y10: Complexity "Importance"
E11: Mass | F11: =AVERAGE(AA11:AP11) -> 0.013877066 | G11: 1 | H11: =1/3 -> 0.33333333 | I11: 1 | J11: =1/2 -> 0.5 | K11: =1/4 -> 0.25 | L11: =1/5 -> 0.2 | M11: =1/3 -> 0.33333333 | N11: =1/2 -> 0.5 | O11: =1/2 -> 0.5 | P11: =1/5 -> 0.2 | Q11: =1/2 -> 0.5 | R11: =1/5 -> 0.2 | S11: =1/2 -> 0.5 | T11: =1/7 -> 0.14285714 | U11: =1/7 -> 0.14285714 | V11: =1/9 -> 0.11111111 | X11: =E11 -> Mass | Y11: =F11 -> 0.013877066 | AA11: =G11/SUM(G$11:G$26) -> 0.016666667 | AB11: =H11/SUM(H$11:H$26) -> 0.0093457944 | AC11: =I11/SUM(I$11:I$26) -> 0.016666667 | AD11: =J11/SUM(J$11:J$26) -> 0.0087719298 | AE11: =K11/SUM(K$11:K$26) -> 0.0050251256 | AF11: =L11/SUM(L$11:L$26) -> 0.012145749 | AG11: =M11/SUM(M$11:M$26) -> 0.01055409 | AH11: =N11/SUM(N$11:N$26) -> 0.015625 | ... AP11: =V11/SUM(V$11:V$26) -> 0.033524904
E12: Information | F12: =AVERAGE(AA12:AP12) -> 0.028774565 | G12: {=1/INDEX($H$11:$V$11, 1, ROW(A1))} -> 3 | H12: 1 | I12: 3 | J12: 2 | K12: 1 | L12: =1/3 -> 0.33333333 | M12: =1/2 -> 0.5 | N12: 1 | O12: 1 | P12: =1/3 -> 0.33333333 | Q12: 2 | R12: =1/3 -> 0.33333333 | S12: =1/2 -> 0.5 | T12: =1/5 -> 0.2 | U12: =1/5 -> 0.2 | V12: =1/7 -> 0.14285714 | X12: =E12 -> Information | Y12: =F12 -> 0.028774565 | AA12: =G12/SUM(G$11:G$26) -> 0.05 | AB12: =H12/SUM(H$11:H$26) -> 0.028037383 | AC12: =I12/SUM(I$11:I$26) -> 0.05 | AD12: =J12/SUM(J$11:J$26) -> 0.035087719 | AE12: =K12/SUM(K$11:K$26) -> 0.020100503 | AF12: =L12/SUM(L$11:L$26) -> 0.020242915 | AG12: =M12/SUM(M$11:M$26) -> 0.015831135 | AH12: =N12/SUM(N$11:N$26) -> 0.03125 | ... AP12: =V12/SUM(V$11:V$26) -> 0.043103448
E13: Physical | F13: =AVERAGE(AA13:AP13) -> 0.013877066 | G13: {=1/INDEX($H$11:$V$11, 1, ROW(A2))} -> 1 | H13: {=1/INDEX($I$12:$V$12, 1, ROW(A1))} -> 0.33333333 | I13: 1 | J13: =1/2 -> 0.5 | K13: =1/4 -> 0.25 | L13: =1/5 -> 0.2 | M13: =1/3 -> 0.33333333 | N13: =1/2 -> 0.5 | O13: =1/2 -> 0.5 | P13: =1/5 -> 0.2 | Q13: =1/2 -> 0.5 | R13: =1/5 -> 0.2 | S13: =1/2 -> 0.5 | T13: =1/7 -> 0.14285714 | U13: =1/7 -> 0.14285714 | V13: =1/9 -> 0.11111111 | X13: =E13 -> Physical | Y13: =F13 -> 0.013877066 | AA13: =G13/SUM(G$11:G$26) -> 0.016666667 | AB13: =H13/SUM(H$11:H$26) -> 0.0093457944 | AC13: =I13/SUM(I$11:I$26) -> 0.016666667 | AD13: =J13/SUM(J$11:J$26) -> 0.0087719298 | AE13: =K13/SUM(K$11:K$26) -> 0.0050251256 | AF13: =L13/SUM(L$11:L$26) -> 0.012145749 | AG13: =M13/SUM(M$11:M$26) -> 0.01055409 | AH13: =N13/SUM(N$11:N$26) -> 0.015625 | ... AP13: =V13/SUM(V$11:V$26) -> 0.033524904
E14: Energy | F14: =AVERAGE(AA14:AP14) -> 0.016800701 | G14: {=1/INDEX($H$11:$V$11, 1, ROW(A3))} -> 2 | H14: {=1/INDEX($I$12:$V$12, 1, ROW(A2))} -> 0.5 | I14: {=1/INDEX($J$13:$V$13, 1, ROW(A1))} -> 2 | J14: 1 | K14: =1/4 -> 0.25 | L14: =1/5 -> 0.2 | M14: =1/3 -> 0.33333333 | N14: =1/2 -> 0.5 | O14: =1/2 -> 0.5 | P14: =1/5 -> 0.2 | Q14: =1/2 -> 0.5 | R14: =1/5 -> 0.2 | S14: =1/2 -> 0.5 | T14: =1/7 -> 0.14285714 | U14: =1/7 -> 0.14285714 | V14: =1/9 -> 0.11111111 | X14: =E14 -> Energy | Y14: =F14 -> 0.016800701 | AA14: =G14/SUM(G$11:G$26) -> 0.033333333 | AB14: =H14/SUM(H$11:H$26) -> 0.014018692 | AC14: =I14/SUM(I$11:I$26) -> 0.033333333 | AD14: =J14/SUM(J$11:J$26) -> 0.01754386 | AE14: =K14/SUM(K$11:K$26) -> 0.0050251256 | AF14: =L14/SUM(L$11:L$26) -> 0.012145749 | AG14: =M14/SUM(M$11:M$26) -> 0.01055409 | AH14: =N14/SUM(N$11:N$26) -> 0.015625 | ... AP14: =V14/SUM(V$11:V$26) -> 0.033524904
E15: Contribution | F15: =AVERAGE(AA15:AP15) -> 0.027463825 | G15: {=1/INDEX($H$11:$V$11, 1, ROW(A4))} -> 4 | H15: {=1/INDEX($I$12:$V$12, 1, ROW(A3))} -> 1 | I15: {=1/INDEX($J$13:$V$13, 1, ROW(A2))} -> 4 | J15: {=1/INDEX($K$14:$V$14, 1, ROW(A1))} -> 4 | K15: 1 | L15: =1/5 -> 0.2 | M15: =1/3 -> 0.33333333 | N15: =1/2 -> 0.5 | O15: 1 | P15: =1/5 -> 0.2 | Q15: 1 | R15: =1/5 -> 0.2 | S15: =1/2 -> 0.5 | T15: =1/7 -> 0.14285714 | U15: =1/7 -> 0.14285714 | V15: =1/9 -> 0.11111111 | X15: =E15 -> Contribution | Y15: =F15 -> 0.027463825 | AA15: =G15/SUM(G$11:G$26) -> 0.066666667 | AB15: =H15/SUM(H$11:H$26) -> 0.028037383 | AC15: =I15/SUM(I$11:I$26) -> 0.066666667 | AD15: =J15/SUM(J$11:J$26) -> 0.070175439 | AE15: =K15/SUM(K$11:K$26) -> 0.020100503 | AF15: =L15/SUM(L$11:L$26) -> 0.012145749 | AG15: =M15/SUM(M$11:M$26) -> 0.01055409 | AH15: =N15/SUM(N$11:N$26) -> 0.015625 | ... AP15: =V15/SUM(V$11:V$26) -> 0.033524904
E16: Development | F16: =AVERAGE(AA16:AP16) -> 0.072329609 | G16: {=1/INDEX($H$11:$V$11, 1, ROW(A5))} -> 5 | H16: {=1/INDEX($I$12:$V$12, 1, ROW(A4))} -> 3 | I16: {=1/INDEX($J$13:$V$13, 1, ROW(A3))} -> 5 | J16: {=1/INDEX($K$14:$V$14, 1, ROW(A2))} -> 5 | K16: {=1/INDEX($L$15:$V$15, 1, ROW(A1))} -> 5 | L16: 1 | M16: 3 | N16: 3 | O16: 3 | P16: 2 | Q16: 2 | R16: =1/2 -> 0.5 | S16: 3 | T16: =1/2 -> 0.5 | U16: =1/3 -> 0.33333333 | V16: =1/5 -> 0.2 | X16: =E16 -> Development | Y16: =F16 -> 0.072329609 | AA16: =G16/SUM(G$11:G$26) -> 0.083333333 | AB16: =H16/SUM(H$11:H$26) -> 0.08411215 | AC16: =I16/SUM(I$11:I$26) -> 0.083333333 | AD16: =J16/SUM(J$11:J$26) -> 0.087719298 | AE16: =K16/SUM(K$11:K$26) -> 0.10050251 | AF16: =L16/SUM(L$11:L$26) -> 0.060728745 | AG16: =M16/SUM(M$11:M$26) -> 0.094986807 | AH16: =N16/SUM(N$11:N$26) -> 0.09375 | ... AP16: =V16/SUM(V$11:V$26) -> 0.060344828
E17: Operation | F17: =AVERAGE(AA17:AP17) -> 0.039499062 | G17: {=1/INDEX($H$11:$V$11, 1, ROW(A6))} -> 3 | H17: {=1/INDEX($I$12:$V$12, 1, ROW(A5))} -> 2 | I17: {=1/INDEX($J$13:$V$13, 1, ROW(A4))} -> 3 | J17: {=1/INDEX($K$14:$V$14, 1, ROW(A3))} -> 3 | K17: {=1/INDEX($L$15:$V$15, 1, ROW(A2))} -> 3 | L17: {=1/INDEX($M$16:$V$16, 1, ROW(A1))} -> 0.33333333 | M17: 1 | N17: =1/2 -> 0.5 | O17: 4 | P17: =1/2 -> 0.5 | Q17: 2 | R17: =1/3 -> 0.33333333 | S17: 1 | T17: =1/5 -> 0.2 | U17: =1/5 -> 0.2 | V17: =1/7 -> 0.14285714 | X17: =E17 -> Operation | Y17: =F17 -> 0.039499062 | AA17: =G17/SUM(G$11:G$26) -> 0.05 | AB17: =H17/SUM(H$11:H$26) -> 0.056074766 | AC17: =I17/SUM(I$11:I$26) -> 0.05 | AD17: =J17/SUM(J$11:J$26) -> 0.052631579 | AE17: =K17/SUM(K$11:K$26) -> 0.060301508 | AF17: =L17/SUM(L$11:L$26) -> 0.020242915 | AG17: =M17/SUM(M$11:M$26) -> 0.031662269 | AH17: =N17/SUM(N$11:N$26) -> 0.015625 | ... AP17: =V17/SUM(V$11:V$26) -> 0.043103448
E18: Service | F18: =AVERAGE(AA18:AP18) -> 0.032182246 | G18: {=1/INDEX($H$11:$V$11, 1, ROW(A7))} -> 2 | H18: {=1/INDEX($I$12:$V$12, 1, ROW(A6))} -> 1 | I18: {=1/INDEX($J$13:$V$13, 1, ROW(A5))} -> 2 | J18: {=1/INDEX($K$14:$V$14, 1, ROW(A4))} -> 2 | K18: {=1/INDEX($L$15:$V$15, 1, ROW(A3))} -> 2 | L18: {=1/INDEX($M$16:$V$16, 1, ROW(A2))} -> 0.33333333 | M18: {=1/INDEX($N$17:$V$17, 1, ROW(A1))} -> 2 | N18: 1 | O18: 2 | P18: =1/2 -> 0.5 | Q18: 1 | R18: =1/3 -> 0.33333333 | S18: 1 | T18: =1/5 -> 0.2 | U18: =1/5 -> 0.2 | V18: =1/7 -> 0.14285714 | X18: =E18 -> Service | Y18: =F18 -> 0.032182246 | AA18: =G18/SUM(G$11:G$26) -> 0.033333333 | AB18: =H18/SUM(H$11:H$26) -> 0.028037383 | AC18: =I18/SUM(I$11:I$26) -> 0.033333333 | AD18: =J18/SUM(J$11:J$26) -> 0.035087719 | AE18: =K18/SUM(K$11:K$26) -> 0.040201005 | AF18: =L18/SUM(L$11:L$26) -> 0.020242915 | AG18: =M18/SUM(M$11:M$26) -> 0.063324538 | AH18: =N18/SUM(N$11:N$26) -> 0.03125 | ... AP18: =V18/SUM(V$11:V$26) -> 0.043103448
E19: Prerequisite | F19: =AVERAGE(AA19:AP19) -> 0.025862154 | G19: {=1/INDEX($H$11:$V$11, 1, ROW(A8))} -> 2 | H19: {=1/INDEX($I$12:$V$12, 1, ROW(A7))} -> 1 | I19: {=1/INDEX($J$13:$V$13, 1, ROW(A6))} -> 2 | J19: {=1/INDEX($K$14:$V$14, 1, ROW(A5))} -> 2 | K19: {=1/INDEX($L$15:$V$15, 1, ROW(A4))} -> 1 | L19: {=1/INDEX($M$16:$V$16, 1, ROW(A3))} -> 0.33333333 | M19: {=1/INDEX($N$17:$V$17, 1, ROW(A2))} -> 0.25 | N19: {=1/INDEX($O$18:$V$18, 1, ROW(A1))} -> 0.5 | O19: 1 | P19: =1/2 -> 0.5 | Q19: 3 | R19: =1/4 -> 0.25 | S19: 1 | T19: =1/9 -> 0.11111111 | U19: =1/9 -> 0.11111111 | V19: =1/9 -> 0.11111111 | X19: =E19 -> Prerequisite | Y19: =F19 -> 0.025862154 | AA19: =G19/SUM(G$11:G$26) -> 0.033333333 | AB19: =H19/SUM(H$11:H$26) -> 0.028037383 | AC19: =I19/SUM(I$11:I$26) -> 0.033333333 | AD19: =J19/SUM(J$11:J$26) -> 0.035087719 | AE19: =K19/SUM(K$11:K$26) -> 0.020100503 | AF19: =L19/SUM(L$11:L$26) -> 0.020242915 | AG19: =M19/SUM(M$11:M$26) -> 0.0079155673 | AH19: =N19/SUM(N$11:N$26) -> 0.015625 | ... AP19: =V19/SUM(V$11:V$26) -> 0.033524904
E20: Coordination | F20: =AVERAGE(AA20:AP20) -> 0.059569888 | G20: {=1/INDEX($H$11:$V$11, 1, ROW(A9))} -> 5 | H20: {=1/INDEX($I$12:$V$12, 1, ROW(A8))} -> 3 | I20: {=1/INDEX($J$13:$V$13, 1, ROW(A7))} -> 5 | J20: {=1/INDEX($K$14:$V$14, 1, ROW(A6))} -> 5 | K20: {=1/INDEX($L$15:$V$15, 1, ROW(A5))} -> 5 | L20: {=1/INDEX($M$16:$V$16, 1, ROW(A4))} -> 0.5 | M20: {=1/INDEX($N$17:$V$17, 1, ROW(A3))} -> 2 | N20: {=1/INDEX($O$18:$V$18, 1, ROW(A2))} -> 2 | O20: {=1/INDEX($P$19:$V$19, 1, ROW(A1))} -> 2 | P20: 1 | Q20: 5 | R20: =1/3 -> 0.33333333 | S20: 2 | T20: =1/5 -> 0.2 | U20: =1/7 -> 0.14285714 | V20: =1/9 -> 0.11111111 | X20: =E20 -> Coordination | Y20: =F20 -> 0.059569888 | AA20: =G20/SUM(G$11:G$26) -> 0.083333333 | AB20: =H20/SUM(H$11:H$26) -> 0.08411215 | AC20: =I20/SUM(I$11:I$26) -> 0.083333333 | AD20: =J20/SUM(J$11:J$26) -> 0.087719298 | AE20: =K20/SUM(K$11:K$26) -> 0.10050251 | AF20: =L20/SUM(L$11:L$26) -> 0.030364372 | AG20: =M20/SUM(M$11:M$26) -> 0.063324538 | AH20: =N20/SUM(N$11:N$26) -> 0.0625 | ... AP20: =V20/SUM(V$11:V$26) -> 0.033524904
E21: Definition | F21: =AVERAGE(AA21:AP21) -> 0.023287782 | G21: {=1/INDEX($H$11:$V$11, 1, ROW(A10))} -> 2 | H21: {=1/INDEX($I$12:$V$12, 1, ROW(A9))} -> 0.5 | I21: {=1/INDEX($J$13:$V$13, 1, ROW(A8))} -> 2 | J21: {=1/INDEX($K$14:$V$14, 1, ROW(A7))} -> 2 | K21: {=1/INDEX($L$15:$V$15, 1, ROW(A6))} -> 1 | L21: {=1/INDEX($M$16:$V$16, 1, ROW(A5))} -> 0.5 | M21: {=1/INDEX($N$17:$V$17, 1, ROW(A4))} -> 0.5 | N21: {=1/INDEX($O$18:$V$18, 1, ROW(A3))} -> 1 | O21: {=1/INDEX($P$19:$V$19, 1, ROW(A2))} -> 0.33333333 | P21: {=1/INDEX($Q$20:$V$20, 1, ROW(A1))} -> 0.2 | Q21: 1 | R21: =1/3 -> 0.33333333 | S21: =1/4 -> 0.25 | T21: =1/5 -> 0.2 | U21: =1/5 -> 0.2 | V21: =1/7 -> 0.14285714 | X21: =E21 -> Definition | Y21: =F21 -> 0.023287782 | AA21: =G21/SUM(G$11:G$26) -> 0.033333333 | AB21: =H21/SUM(H$11:H$26) -> 0.014018692 | AC21: =I21/SUM(I$11:I$26) -> 0.033333333 | AD21: =J21/SUM(J$11:J$26) -> 0.035087719 | AE21: =K21/SUM(K$11:K$26) -> 0.020100503 | AF21: =L21/SUM(L$11:L$26) -> 0.030364372 | AG21: =M21/SUM(M$11:M$26) -> 0.015831135 | AH21: =N21/SUM(N$11:N$26) -> 0.03125 | ... AP21: =V21/SUM(V$11:V$26) -> 0.043103448
E22: Contractual | F22: =AVERAGE(AA22:AP22) -> 0.08252224 | G22: {=1/INDEX($H$11:$V$11, 1, ROW(A11))} -> 5 | H22: {=1/INDEX($I$12:$V$12, 1, ROW(A10))} -> 3 | I22: {=1/INDEX($J$13:$V$13, 1, ROW(A9))} -> 5 | J22: {=1/INDEX($K$14:$V$14, 1, ROW(A8))} -> 5 | K22: {=1/INDEX($L$15:$V$15, 1, ROW(A7))} -> 5 | L22: {=1/INDEX($M$16:$V$16, 1, ROW(A6))} -> 2 | M22: {=1/INDEX($N$17:$V$17, 1, ROW(A5))} -> 3 | N22: {=1/INDEX($O$18:$V$18, 1, ROW(A4))} -> 3 | O22: {=1/INDEX($P$19:$V$19, 1, ROW(A3))} -> 4 | P22: {=1/INDEX($Q$20:$V$20, 1, ROW(A2))} -> 3 | Q22: {=1/INDEX($R$21:$V$21, 1, ROW(A1))} -> 3 | R22: 1 | S22: 2 | T22: =1/2 -> 0.5 | U22: =1/2 -> 0.5 | V22: =1/5 -> 0.2 | X22: =E22 -> Contractual | Y22: =F22 -> 0.08252224 | AA22: =G22/SUM(G$11:G$26) -> 0.083333333 | AB22: =H22/SUM(H$11:H$26) -> 0.08411215 | AC22: =I22/SUM(I$11:I$26) -> 0.083333333 | AD22: =J22/SUM(J$11:J$26) -> 0.087719298 | AE22: =K22/SUM(K$11:K$26) -> 0.10050251 | AF22: =L22/SUM(L$11:L$26) -> 0.12145749 | AG22: =M22/SUM(M$11:M$26) -> 0.094986807 | AH22: =N22/SUM(N$11:N$26) -> 0.09375 | ... AP22: =V22/SUM(V$11:V$26) -> 0.060344828
E23: Deliverable | F23: =AVERAGE(AA23:AP23) -> 0.036576736 | G23: {=1/INDEX($H$11:$V$11, 1, ROW(A12))} -> 2 | H23: {=1/INDEX($I$12:$V$12, 1, ROW(A11))} -> 2 | I23: {=1/INDEX($J$13:$V$13, 1, ROW(A10))} -> 2 | J23: {=1/INDEX($K$14:$V$14, 1, ROW(A9))} -> 2 | K23: {=1/INDEX($L$15:$V$15, 1, ROW(A8))} -> 2 | L23: {=1/INDEX($M$16:$V$16, 1, ROW(A7))} -> 0.33333333 | M23: {=1/INDEX($N$17:$V$17, 1, ROW(A6))} -> 1 | N23: {=1/INDEX($O$18:$V$18, 1, ROW(A5))} -> 1 | O23: {=1/INDEX($P$19:$V$19, 1, ROW(A4))} -> 1 | P23: {=1/INDEX($Q$20:$V$20, 1, ROW(A3))} -> 0.5 | Q23: {=1/INDEX($R$21:$V$21, 1, ROW(A2))} -> 4 | R23: {=1/INDEX($S$22:$V$22, 1, ROW(A1))} -> 0.5 | S23: 1 | T23: =1/3 -> 0.33333333 | U23: =1/5 -> 0.2 | V23: =1/7 -> 0.14285714 | X23: =E23 -> Deliverable | Y23: =F23 -> 0.036576736 | AA23: =G23/SUM(G$11:G$26) -> 0.033333333 | AB23: =H23/SUM(H$11:H$26) -> 0.056074766 | AC23: =I23/SUM(I$11:I$26) -> 0.033333333 | AD23: =J23/SUM(J$11:J$26) -> 0.035087719 | AE23: =K23/SUM(K$11:K$26) -> 0.040201005 | AF23: =L23/SUM(L$11:L$26) -> 0.020242915 | AG23: =M23/SUM(M$11:M$26) -> 0.031662269 | AH23: =N23/SUM(N$11:N$26) -> 0.03125 | ... AP23: =V23/SUM(V$11:V$26) -> 0.043103448
E24: Financial | F24: =AVERAGE(AA24:AP24) -> 0.12592554 | G24: {=1/INDEX($H$11:$V$11, 1, ROW(A13))} -> 7 | H24: {=1/INDEX($I$12:$V$12, 1, ROW(A12))} -> 5 | I24: {=1/INDEX($J$13:$V$13, 1, ROW(A11))} -> 7 | J24: {=1/INDEX($K$14:$V$14, 1, ROW(A10))} -> 7 | K24: {=1/INDEX($L$15:$V$15, 1, ROW(A9))} -> 7 | L24: {=1/INDEX($M$16:$V$16, 1, ROW(A8))} -> 2 | M24: {=1/INDEX($N$17:$V$17, 1, ROW(A7))} -> 5 | N24: {=1/INDEX($O$18:$V$18, 1, ROW(A6))} -> 5 | O24: {=1/INDEX($P$19:$V$19, 1, ROW(A5))} -> 9 | P24: {=1/INDEX($Q$20:$V$20, 1, ROW(A4))} -> 5 | Q24: {=1/INDEX($R$21:$V$21, 1, ROW(A3))} -> 5 | R24: {=1/INDEX($S$22:$V$22, 1, ROW(A2))} -> 2 | S24: {=1/INDEX($T$23:$V$23, 1, ROW(A1))} -> 3 | T24: 1 | U24: =1/2 -> 0.5 | V24: =1/5 -> 0.2 | X24: =E24 -> Financial | Y24: =F24 -> 0.12592554 | AA24: =G24/SUM(G$11:G$26) -> 0.11666667 | AB24: =H24/SUM(H$11:H$26) -> 0.14018692 | AC24: =I24/SUM(I$11:I$26) -> 0.11666667 | AD24: =J24/SUM(J$11:J$26) -> 0.12280702 | AE24: =K24/SUM(K$11:K$26) -> 0.14070352 | AF24: =L24/SUM(L$11:L$26) -> 0.12145749 | AG24: =M24/SUM(M$11:M$26) -> 0.15831135 | AH24: =N24/SUM(N$11:N$26) -> 0.15625 | ... AP24: =V24/SUM(V$11:V$26) -> 0.060344828
E25: Legal | F25: =AVERAGE(AA25:AP25) -> 0.15074309 | G25: {=1/INDEX($H$11:$V$11, 1, ROW(A14))} -> 7 | H25: {=1/INDEX($I$12:$V$12, 1, ROW(A13))} -> 5 | I25: {=1/INDEX($J$13:$V$13, 1, ROW(A12))} -> 7 | J25: {=1/INDEX($K$14:$V$14, 1, ROW(A11))} -> 7 | K25: {=1/INDEX($L$15:$V$15, 1, ROW(A10))} -> 7 | L25: {=1/INDEX($M$16:$V$16, 1, ROW(A9))} -> 3 | M25: {=1/INDEX($N$17:$V$17, 1, ROW(A8))} -> 5 | N25: {=1/INDEX($O$18:$V$18, 1, ROW(A7))} -> 5 | O25: {=1/INDEX($P$19:$V$19, 1, ROW(A6))} -> 9 | P25: {=1/INDEX($Q$20:$V$20, 1, ROW(A5))} -> 7 | Q25: {=1/INDEX($R$21:$V$21, 1, ROW(A4))} -> 5 | R25: {=1/INDEX($S$22:$V$22, 1, ROW(A3))} -> 2 | S25: {=1/INDEX($T$23:$V$23, 1, ROW(A2))} -> 5 | T25: {=1/INDEX($U$24:$V$24, 1, ROW(A1))} -> 2 | U25: 1 | V25: =1/3 -> 0.33333333 | X25: =E25 -> Legal | Y25: =F25 -> 0.15074309 | AA25: =G25/SUM(G$11:G$26) -> 0.11666667 | AB25: =H25/SUM(H$11:H$26) -> 0.14018692 | AC25: =I25/SUM(I$11:I$26) -> 0.11666667 | AD25: =J25/SUM(J$11:J$26) -> 0.12280702 | AE25: =K25/SUM(K$11:K$26) -> 0.14070352 | AF25: =L25/SUM(L$11:L$26) -> 0.18218623 | AG25: =M25/SUM(M$11:M$26) -> 0.15831135 | AH25: =N25/SUM(N$11:N$26) -> 0.15625 | ... AP25: =V25/SUM(V$11:V$26) -> 0.10057471
E26: Political | F26: =AVERAGE(AA26:AP26) -> 0.25070842 | G26: {=1/INDEX($H$11:$V$11, 1, ROW(A15))} -> 9 | H26: {=1/INDEX($I$12:$V$12, 1, ROW(A14))} -> 7 | I26: {=1/INDEX($J$13:$V$13, 1, ROW(A13))} -> 9 | J26: {=1/INDEX($K$14:$V$14, 1, ROW(A12))} -> 9 | K26: {=1/INDEX($L$15:$V$15, 1, ROW(A11))} -> 9 | L26: {=1/INDEX($M$16:$V$16, 1, ROW(A10))} -> 5 | M26: {=1/INDEX($N$17:$V$17, 1, ROW(A9))} -> 7 | N26: {=1/INDEX($O$18:$V$18, 1, ROW(A8))} -> 7 | O26: {=1/INDEX($P$19:$V$19, 1, ROW(A7))} -> 9 | P26: {=1/INDEX($Q$20:$V$20, 1, ROW(A6))} -> 9 | Q26: {=1/INDEX($R$21:$V$21, 1, ROW(A5))} -> 7 | R26: {=1/INDEX($S$22:$V$22, 1, ROW(A4))} -> 5 | S26: {=1/INDEX($T$23:$V$23, 1, ROW(A3))} -> 7 | T26: {=1/INDEX($U$24:$V$24, 1, ROW(A2))} -> 5 | U26: {=1/INDEX($V$25:$V$25, 1, ROW(A1))} -> 3 | V26: 1 | X26: =E26 -> Political | Y26: =F26 -> 0.25070842 | AA26: =G26/SUM(G$11:G$26) -> 0.15 | AB26: =H26/SUM(H$11:H$26) -> 0.19626168 | AC26: =I26/SUM(I$11:I$26) -> 0.15 | AD26: =J26/SUM(J$11:J$26) -> 0.15789474 | AE26: =K26/SUM(K$11:K$26) -> 0.18090452 | AF26: =L26/SUM(L$11:L$26) -> 0.30364372 | AG26: =M26/SUM(M$11:M$26) -> 0.22163588 | AH26: =N26/SUM(N$11:N$26) -> 0.21875 | ... AP26: =V26/SUM(V$11:V$26) -> 0.30172414
F27: =SUM(F11:F26) -> 1

Sheet Financial Interface
A1: Compared Interface | B1: Saaty Score | C1: Explanation
A2: Legal | B2: 1/2 | C2: Legal interfaces include regulatory enforcement and compliance regimes that often govern financial mechanisms, making them slightly more complex. | E2: 1/2 | F2: 1/5
A3: Political | B3: 1/5 | C3: Political interfaces add instability, jurisdictional overlap, and stakeholder-driven conflict, making them significantly more complex than financial structures.

Sheet Legal Interface
A1: Compared Interface | B1: Saaty Score | C1: Explanation
A2: Political | B2: 1/3 | C2: Legal interfaces are structured around defined rules and compliance processes, while political interfaces introduce uncertainty, stakeholder conflict, and dynamic jurisdictional challenges—making them more complex overall.

Sheet Operation Interface
A1: Compared Interface | B1: Saaty Score | C1: Explanation
A2: Service | B2: 1/2 | C2: Service interfaces introduce maintenance scheduling and dependency management, which adds more lifecycle complexity than real-time operations alone. | E2: 1/2 | F2: 3 | G2: 1/2 | H2: 1/2 | I2: 1/3 | J2: 1 | K2: 1/5 | L2: 1/5 | M2: 1/7
A3: Prerequisite | B3: 3 | C3: Operations are dynamic and involve decision-making and execution, whereas prerequisites are static temporal conditions.
A4: Coordination | B4: 1/2 | C4: While operations are complex, coordination involves dynamic synchronization across domains, often making it slightly more complex.
A5: Definition | B5: 1/2 | C5: Definition interfaces determine the scope and control of operations; they shape them but are often more abstract and systemic.
A6: Contractual | B6: 1/3 | C6: Contracts govern who operates what, with embedded legal and financial structures, introducing significantly more oversight complexity.
A7: Deliverable | B7: 1 | C7: Deliverables and operations are similar in structure and execution demands, with neither clearly more complex in all cases.
A8: Financial | B8: 1/5 | C8: Financial interfaces involve budget cycles, reimbursements, and governance, far more complex than executing plans.
A9: Legal | B9: 1/5 | C9: Legal constraints can block, enable, or complicate operations — often introducing layers of complexity beyond tactical execution.
A10: Political | B10: 1/7 | C10: Political factors dictate operational authority and can override plans, making them significantly more complex than operational logic.

Sheet Service Interface
A1: Compared Interface | B1: Saaty Score | C1: Explanation
A2: Prerequisite | B2: 5 | C2: Prerequisite interfaces are logical orderings, while service interfaces involve lifecycle dependencies, maintenance timing, and platform access, which are significantly more complex. | E2: 5 | F2: 1/2 | G2: 1/2 | H2: 1/3 | I2: 1 | J2: 1/5 | K2: 1/5 | L2: 1/7
A3: Coordination | B3: 1/2 | C3: Coordination involves real-time, multi-party alignment, often surpassing the logistical complexity of service activities.
A4: Definition | B4: 1/2 | C4: Definitions shape expectations, processes, and compliance across systems, introducing abstract and far-reaching complexity compared to service logistics.
A5: Contractual | B5: 1/3 | C5: Contracts embed formal expectations, penalties, and legal boundaries, adding more complexity than routine or scheduled service interactions.
A6: Deliverable | B6: 1 | C6: Deliverables and services both require timing, quality assurance, and transfer mechanisms, with comparable complexity.
A7: Financial | B7: 1/5 | C7: Financial interfaces involve budget allocations, cross-jurisdiction agreements, and reimbursement logistics—more complex than service provision.
A8: Legal | B8: 1/5 | C8: Legal interfaces require compliance with regulatory frameworks and audits, adding complexity far beyond physical maintenance.
A9: Political | B9: 1/7 | C9: Political interfaces involve authority negotiations and decision overrides, significantly more complex than executing scheduled services.

Sheet Prereq Interface
A1: Compared Interface | B1: Saaty Score | C1: Explanation
A2: Coordination | B2: 1/5 | C2: Coordination involves dynamic task, timing, and spatial alignment, which adds significantly more complexity than static sequencing logic. | E2: 1/5 | F2: 1/3 | G2: 1/7 | H2: 1/2 | I2: 1/9 | J2: 1/9 | K2: 1/9
A3: Definition | B3: 1/3 | C3: Definitions set standards and execution rules across organizations, adding more systemic complexity than a simple prerequisite condition.
A4: Contractual | B4: 1/7 | C4: Contracts govern rights, obligations, and penalties, introducing legal and organizational complexity far beyond functional dependencies.
A5: Deliverable | B5: 1/2 | C5: Deliverables involve format, content, timing, and quality control, making them moderately more complex than temporal preconditions.
A6: Financial | B6: 1/9 | C6: Financial agreements span budgeting, reimbursement, and multilateral funding structures, introducing deep systemic complexity.
A7: Legal | B7: 1/9 | C7: Legal constraints affect compliance, policy interpretation, and enforcement, far more complex than functional logic sequencing.
A8: Political | B8: 1/9 | C8: Political interfaces involve authority struggles, prioritization shifts, and jurisdictional disputes—orders of magnitude more complex.

Sheet Coordination Interface
A1: Compared Interface | B1: Saaty Score | C1: Explanation
A2: Definition | B2: 1 | C2: Both coordination and definition shape how functions operate—coordination dynamically aligns execution, while definition frames it structurally. | E2: 1 | F2: 1/3 | G2: 2 | H2: 1/5 | I2: 1/7 | J2: 1/9
A3: Contractual | B3: 1/3 | C3: Contracts carry legal weight, compliance monitoring, and risk management—adding more complexity than dynamic task alignment.
A4: Deliverable | B4: 2 | C4: Deliverables are output-specific and bounded, whereas coordination spans timing, location, and interdependencies across systems.
A5: Financial | B5: 1/5 | C5: Financial structures involve authority, timelines, and often politics—adding deeply embedded complexity compared to synchronization efforts.
A6: Legal | B6: 1/7 | C6: Legal systems include constraints, enforcement mechanisms, and regulation, introducing more systemic burden than coordination.
A7: Political | B7: 1/9 | C7: Political dynamics bring unpredictability, competing interests, and jurisdictional overlays, far more complex than operational coordination.

Sheet Definition Interface
A1: Compared Interface | B1: Saaty Score | C1: Explanation
A2: Contractual | B2: 1/3 | C2: Contracts introduce legal enforceability, obligations, and penalties, making them more complex than the structural role of definitions. | E2: 1/3 | F2: 2 | G2: 1/5 | H2: 1/5 | I2: 1/7
A3: Deliverable | B3: 2 | C3: Definitions set the scope and frequency of deliverables, but deliverables are bounded tasks, giving definitions more systemic influence.
A4: Financial | B4: 1/5 | C4: Financial interfaces involve multi-party funding flows and controls—more layered and bureaucratic than scope-setting definitions.
A5: Legal | B5: 1/5 | C5: Legal interfaces carry regulatory enforcement, which can override or restrict definitions and create institutional complexity.
A6: Political | B6: 1/7 | C6: Political interfaces introduce dynamic and unpredictable authority conflicts that far exceed the procedural role of definitions.

Sheet Contractual Interface
A1: Compared Interface | B1: Saaty Score | C1: Explanation
A2: Deliverable | B2: 2 | C2: Contracts define expectations, timelines, penalties, and enforcement, which makes them more complex than bounded output-based deliverables. | E2: 2 | F2: 1/2 | G2: 1/2 | H2: 1/5
A3: Financial | B3: 1/2 | C3: Financial interfaces can be more complex due to budget cycles, cost-sharing arrangements, and reimbursement procedures crossing agencies and fiscal systems.
A4: Legal | B4: 1/2 | C4: While contracts may be legally binding, legal interfaces span laws, enforcement, and compliance audits—often more systemically complex.
A5: Political | B5: 1/5 | C5: Political interfaces involve stakeholder power, negotiations, and external overrides, making them significantly more complex than contractual agreements.

Sheet Energy Interface
A1: Compared Interface | B1: Saaty Score | C1: Explanation
A2: Contribution | B2: 1 | C2: Energy and contribution interfaces both support other systems, but energy requires technical integration and reliability management. | E2: 1 | F2: 1/5 | G2: 1/3 | H2: 1/2 | I2: 2 | J2: 1/5 | K2: 1/3 | L2: 1/5 | M2: 1/2 | N2: 1/7 | O2: 1/7 | P2: 1/9
A3: Development | B3: 1/5 | C3: Co-development introduces long-term architectural, institutional, and scheduling complexity far beyond energy supply interfaces.
A4: Operation | B4: 1/3 | C4: Operational interfaces involve control, execution, and authority complexity, which is higher than technical power transfer.
A5: Service | B5: 1/2 | C5: Service includes diagnostic, scheduling, and physical access complexity, making it somewhat more complex than energy flow.
A6: Prerequisite | B6: 2 | C6: Sequencing interfaces are simpler logic constructs compared to continuous technical energy delivery.
A7: Coordination | B7: 1/5 | C7: Coordinating across domains and timescales introduces dynamic complexity well beyond power provisioning.
A8: Definition | B8: 1/3 | C8: Defining functional boundaries and performance scope can impact multiple systems and introduce more abstract complexity than energy delivery.
A9: Contractual | B9: 1/5 | C9: Contracts bring in legal, operational, and financial implications, significantly more complex than technical power interfaces.
A10: Deliverable | B10: 1/2 | C10: Deliverables often bundle outputs and may involve multiple systems, making them more complex than steady energy exchange.
A11: Financial | B11: 1/7 | C11: Financial interfaces require budget alignment and authority, adding complexity layers energy transfer lacks.
A12: Legal | B12: 1/7 | C12: Legal restrictions, enforcement, and liability structures add far more systemic complexity than technical power coupling.
A13: Political | B13: 1/9 | C13: Power dynamics, jurisdictional control, and unpredictability in political interfaces vastly exceed technical energy concerns.

Sheet Contribution Interface
A1: Compared Interface | B1: Saaty Score | C1: Explanation
A2: Development | B2: 1/5 | C2: Development involves co-creation and architectural integration over time, making it significantly more complex than simple functional contribution. | E2: 1/5 | F2: 1/3 | G2: 1/2 | H2: 2 | I2: 1/5 | J2: 1/3 | K2: 1/5 | L2: 1/2 | M2: 1/7 | N2: 1/7 | O2: 1/9
A3: Operation | B3: 1/3 | C3: Operational interfaces require dynamic execution and shared control, which is more complex than enabling support through contribution.
A4: Service | B4: 1/2 | C4: Services involve logistics, maintenance schedules, and system compatibility, which add more complexity than static contribution relationships.
A5: Prerequisite | B5: 2 | C5: Sequencing logic is simpler than a structural or enabling function, making contribution moderately more complex.
A6: Coordination | B6: 1/5 | C6: Coordination requires synchronization across elements, teams, or timelines, making it far more complex than a one-way contribution.
A7: Definition | B7: 1/3 | C7: Definition impacts purpose, scope, and standardization, introducing higher-level complexity than enabling a function.
A8: Contractual | B8: 1/5 | C8: Contracts embed legal, financial, and operational constraints that exceed the complexity of enabling contribution.
A9: Deliverable | B9: 1/2 | C9: Deliverables typically specify timing and format, adding a structured complexity greater than ongoing functional contribution.
A10: Financial | B10: 1/7 | C10: Financial flows span multiple levels of abstraction — funding, control, and reimbursement — far more complex than functional support.
A11: Legal | B11: 1/7 | C11: Legal constraints can change over time, limit behavior, and add documentation requirements, which go beyond contributions.
A12: Political | B12: 1/9 | C12: Political interfaces involve ambiguity, control struggles, and stakeholder coordination, which are orders of magnitude more complex.

Sheet Development Interface
A1: Compared Interface | B1: Saaty Score | C1: Explanation
A2: Operation | B2: 3 | C2: Operations involve execution and control, but development involves multi-phase collaboration, technical integration, and long-term co-design, which adds more systemic complexity. | E2: 3 | F2: 3 | G2: 7 | H2: 2 | I2: 2 | J2: 1/2 | K2: 3 | L2: 1/2 | M2: 1/3 | N2: 1/5
A3: Service | B3: 3 | C3: While services involve lifecycle management, development introduces strategic and architectural alignment, which is more complex over time.
A4: Prerequisite | B4: 7 | C4: A prerequisite is a simple temporal logic, while development requires deep integration and planning, making it significantly more complex.
A5: Coordination | B5: 2 | C5: Coordination requires dynamic alignment, but development carries multi-stage, multi-stakeholder technical and organizational complexity.
A6: Definition | B6: 2 | C6: Definitions formalize scope and behavior, but development requires execution of that scope collaboratively, which adds implementation complexity.
A7: Contractual | B7: 1/2 | C7: Contracts can enforce and govern development work, and may add compliance and negotiation layers that outpace even technical complexity.
A8: Deliverable | B8: 3 | C8: A deliverable is a bounded output, while development is iterative, ongoing, and requires feedback, making it structurally more complex.
A9: Financial | B9: 1/2 | C9: Financial structures can be multi-tiered and politically influenced, sometimes making them even more complex than development agreements.
A10: Legal | B10: 1/3 | C10: Legal frameworks include enforcement, regulation, and documentation that often span and constrain development itself.
A11: Political | B11: 1/5 | C11: Political interfaces are highly unpredictable and involve power struggles, making them more complex than even multilateral development.

Sheet Mass Interface
A1: Compared Interface | B1: Saaty Score | C1: Explanation
A2: Information | B2: 1/3 | C2: Mass flows are typically more tangible and discrete, while information flows add complexity via routing, interpretation, and latency. | E2: 1/3 | F2: 1 | G2: 1/2 | H2: 1/2 | I2: 1/5 | J2: 1/3 | K2: 1/2 | L2: 2 | M2: 1/5 | N2: 1/5 | O2: 1/5 | P2: 1/2 | Q2: 1/7 | R2: 1/7 | S2: 1/9
A3: Physical | B3: 1 | C3: Both involve physical interaction; neither is significantly more complex than the other in most scenarios.
A4: Energy | B4: 1/2 | C4: Energy interfaces require compatibility and continuous management (e.g., power compatibility), making them slightly more complex.
A5: Contribution | B5: 1/2 | C5: Contribution interfaces add semantic and architectural dependencies, introducing more abstract complexity.
A6: Development | B6: 1/5 | C6: Co-development requires IP alignment, timeline sync, and architectural integration, adding far more complexity than physical mass transfer.
A7: Operation | B7: 1/3 | C7: Shared or delegated operations add organizational coordination complexity.
A8: Service | B8: 1/2 | C8: Service interfaces involve scheduling, maintenance cycles, and hardware access, which can be more complex than one-way mass flow.
A9: Prerequisite | B9: 2 | C9: A prerequisite is just a sequencing logic and generally simpler than physical exchange interfaces.
A10: Coordination | B10: 1/5 | C10: Cross-domain coordination (timing/location) introduces far more complexity than physical transport.
A11: Definition | B11: 1/5 | C11: Defining a function's scope/purpose impacts many elements and introduces policy and documentation complexity.
A12: Contractual | B12: 1/5 | C12: Formal contracts embed legal, operational, and financial terms, much more complex than physical delivery.
A13: Deliverable | B13: 1/2 | C13: Deliverables can span digital/physical and are often embedded in broader workflows, slightly more complex than mass.
A14: Financial | B14: 1/7 | C14: Funding agreements span agencies and timelines — significantly more complex than physical exchange.
... A16: Political | B16: 1/9 | C16: Political interfaces involve stakeholders, power dynamics, and unpredictability — the most complex domain.

Sheet Information Interface
A1: Compared Interface | B1: Saaty Score | C1: Explanation
A2: Physical | B2: 3 | C2: Information flows are more abstract and often require integration with networks, software, and interpretation layers, adding more complexity than simple physical interfaces. | E2: 3 | F2: 2 | G2: 2 | H2: 1/3 | I2: 1/2 | J2: 1 | K2: 3 | L2: 1/3 | M2: 1/2 | N2: 1/3 | O2: 1/2 | P2: 1/5 | Q2: 1/5 | R2: 1/7
A3: Energy | B3: 2 | C3: Energy flows require hardware compatibility and continuous delivery, but information interfaces often involve data models, latency, and protocol management.
A4: Contribution | B4: 2 | C4: Contributing functions can be abstract, but they usually don't involve the same integration and data processing layers as information interfaces.
A5: Development | B5: 1/3 | C5: Co-development introduces architectural integration and long-term complexity, often exceeding that of information flows.
A6: Operation | B6: 1/2 | C6: Joint or delegated operations involve command, control, and responsibility handoffs, which can exceed the complexity of pure information exchange.
A7: Service | B7: 1 | C7: Both information and service interfaces depend on timing and access; neither is clearly more complex in all contexts.
A8: Prerequisite | B8: 3 | C8: Sequencing constraints are simple compared to managing data interpretation, latency, and continuous flow.
A9: Coordination | B9: 1/3 | C9: Cross-domain coordination adds dynamic, time-critical complexity that exceeds that of typical data exchange.
A10: Definition | B10: 1/2 | C10: Defining a function adds institutional, semantic, and structural constraints that often affect downstream systems more than data flow.
A11: Contractual | B11: 1/3 | C11: Contracts include legal and performance implications beyond those of data transmission, making them more complex.
A12: Deliverable | B12: 1/2 | C12: Deliverables can be information-based, but are bounded and structured, whereas raw information flow often lacks that clarity.
A13: Financial | B13: 1/5 | C13: Financial agreements span timelines, stakeholders, and budgets, adding substantially more complexity than data interfaces.
A14: Legal | B14: 1/5 | C14: Legal interfaces include regulations, enforcement, and compliance structures, making them more complex than data flows.
